Workbook

Sheet Dashboard bkp
A1: Personal Finance Dashboard 2026
B3: Total Expense | E3: Monthly Average Expense | I3: Personal Savings | L3: Investment Savings
B4: 363250 | E4: =AVERAGE(L9:L20) -> 30270.833 | I4: 30000 | L4: 230000
C7: EXPENSES | M7: SAVINGS
A8: Year | B8: Month | C8: Home Rent | D8: Transport | E8: Shopping | F8: Office | G8: Bills | H8: Insurance | I8: Medical | J8: Fitness | K8: Misc | L8: Total Spent | M8: Investments | N8: Personal
A9: 2026 | B9: Jan | C9: 16000 | D9: 1200 | E9: 4500 | F9: 2500 | G9: 1800 | H9: 2500 | I9: 800 | J9: 1000 | K9: 700 | L9: 29000 | M9: 20000 | N9: 2500
A10: 2026 | B10: Feb | C10: 16000 | D10: 900 | E10: 3200 | F10: 2200 | G10: 1750 | H10: 2500 | I10: 500 | J10: 0 | K10: 300 | L10: 27350 | M10: 18000 | N10: 2500
A11: 2026 | B11: Mar | C11: 16000 | D11: 1500 | E11: 6000 | F11: 2800 | G11: 1900 | H11: 2500 | I11: 1200 | J11: 1500 | K11: 600 | L11: 34000 | M11: 25000 | N11: 2500
A12: 2026 | B12: Apr | C12: 16000 | D12: 800 | E12: 2500 | F12: 2100 | G12: 1700 | H12: 2500 | I12: 300 | J12: 0 | K12: 400 | L12: 26300 | M12: 22000 | N12: 2500
A13: 2026 | B13: May | C13: 16000 | D13: 1300 | E13: 7500 | F13: 3000 | G13: 1800 | H13: 2500 | I13: 700 | J13: 1000 | K13: 500 | L13: 34300 | M13: 15000 | N13: 2500
A14: 2026 | B14: Jun | C14: 16000 | D14: 1000 | E14: 2800 | F14: 2400 | G14: 1750 | H14: 2500 | I14: 600 | J14: 500 | K14: 350 | L14: 27900 | M14: 20000 | N14: 2500
A15: 2026 | B15: Jul | C15: 16000 | D15: 1100 | E15: 3500 | F15: 2600 | G15: 1800 | H15: 2500 | I15: 450 | J15: 1000 | K15: 400 | L15: 29350 | M15: 18000 | N15: 2500
A16: 2026 | B16: Aug | C16: 16000 | D16: 900 | E16: 4200 | F16: 2300 | G16: 1700 | H16: 2500 | I16: 550 | J16: 0 | K16: 300 | L16: 28450 | M16: 21000 | N16: 2500
A17: 2026 | B17: Sep | C17: 16000 | D17: 1400 | E17: 3100 | F17: 2500 | G17: 1850 | H17: 2500 | I17: 700 | J17: 800 | K17: 450 | L17: 29300 | M17: 19000 | N17: 2500
A18: 2026 | B18: Oct | C18: 16000 | D18: 1200 | E18: 5000 | F18: 2700 | G18: 1800 | H18: 2500 | I18: 900 | J18: 1000 | K18: 600 | L18: 31700 | M18: 17000 | N18: 2500
A19: 2026 | B19: Nov | C19: 16000 | D19: 1000 | E19: 3800 | F19: 2400 | G19: 1750 | H19: 2500 | I19: 500 | J19: 500 | K19: 350 | L19: 28800 | M19: 23000 | N19: 2500
A20: 2026 | B20: Dec | C20: 16000 | D20: 1800 | E20: 8500 | F20: 3500 | G20: 2000 | H20: 2500 | I20: 1500 | J20: 0 | K20: 1000 | L20: 36800 | M20: 12000 | N20: 2500
A21: Year Total | C21: =SUM(C9:C20) -> 192000 | D21: =SUM(D9:D20) -> 14100 | E21: =SUM(E9:E20) -> 54600 | F21: =SUM(F9:F20) -> 31000 | G21: =SUM(G9:G20) -> 21600 | H21: =SUM(H9:H20) -> 30000 | I21: =SUM(I9:I20) -> 8700 | J21: =SUM(J9:J20) -> 7300 | ... N21: =SUM(N9:N20) -> 30000

Sheet Dashboard
A1: Personal Finance Dashboard
A3: Year | C3: Total Expense | E3: Monthly Avg Expense | H3: Personal Savings | K3: Investment Savings | O3: Total Savings | Z3: Year
A4: 2026 | C4: =SUMIF(Database!A:A,A4,Database!M:M) -> 234266.21 | E4: =AVERAGEIFS(Database!M:M,Database!A:A,A4,Database!M:M,">0") -> 39044.368 | H4: =SUMIF(Database!A:A,A4,Database!O:O) -> 210000 | K4: =SUMIF(Database!A:A,A4,Database!N:N) -> 60000 | O4: =SUMIF(Database!A:A,A4,Database!P:P) -> 270000 | Z4: 2022
Z5: 2023
C6: EXPENSES | N6: SAVINGS | Z6: 2024
A7: Year | B7: Month | C7: Home Rent | D7: Transport | E7: Shopping | F7: Office | G7: Bills | H7: Insurance | I7: Medical | J7: Fitness | K7: Travel | L7: Misc | M7: Total Spent | N7: Investment | O7: Personal | P7: Total Savings | Z7: 2025
A8: =$A$4 -> 2026 | B8: Jan | C8: =SUMIFS(Database!$C:$C,Database!$A:$A,$A$4,Database!$B:$B,$B8) -> 0 | D8: =SUMIFS(Database!$D:$D,Database!$A:$A,$A$4,Database!$B:$B,$B8) -> 14.25 | E8: =SUMIFS(Database!$E:$E,Database!$A:$A,$A$4,Database!$B:$B,$B8) -> 16919.21 | F8: =SUMIFS(Database!$F:$F,Database!$A:$A,$A$4,Database!$B:$B,$B8) -> 0 | G8: =SUMIFS(Database!$G:$G,Database!$A:$A,$A$4,Database!$B:$B,$B8) -> 119 | H8: =SUMIFS(Database!$H:$H,Database!$A:$A,$A$4,Database!$B:$B,$B8) -> 0 | I8: =SUMIFS(Database!$I:$I,Database!$A:$A,$A$4,Database!$B:$B,$B8) -> 487.55 | J8: =SUMIFS(Database!$J:$J,Database!$A:$A,$A$4,Database!$B:$B,$B8) -> 0 | K8: =SUMIFS(Database!$K:$K,Database!$A:$A,$A$4,Database!$B:$B,$B8) -> 0 | L8: =SUMIFS(Database!$L:$L,Database!$A:$A,$A$4,Database!$B:$B,$B8) -> 0 | M8: =SUMIFS(Database!$M:$M,Database!$A:$A,$A$4,Database!$B:$B,$B8) -> 17540.01 | N8: =SUMIFS(Database!$N:$N,Database!$A:$A,$A$4,Database!$B:$B,$B8) -> 10000 | O8: =SUMIFS(Database!$O:$O,Database!$A:$A,$A$4,Database!$B:$B,$B8) -> 100000 | P8: =SUMIFS(Database!$P:$P,Database!$A:$A,$A8,Database!$B:$B,$B8) -> 110000 | Z8: 2026
A9: =$A$4 -> 2026 | B9: Feb | C9: =SUMIFS(Database!$C:$C,Database!$A:$A,$A$4,Database!$B:$B,$B9) -> 0 | D9: =SUMIFS(Database!$D:$D,Database!$A:$A,$A$4,Database!$B:$B,$B9) -> 234.25 | E9: =SUMIFS(Database!$E:$E,Database!$A:$A,$A$4,Database!$B:$B,$B9) -> 15188.65 | F9: =SUMIFS(Database!$F:$F,Database!$A:$A,$A$4,Database!$B:$B,$B9) -> 0 | G9: =SUMIFS(Database!$G:$G,Database!$A:$A,$A$4,Database!$B:$B,$B9) -> 119 | H9: =SUMIFS(Database!$H:$H,Database!$A:$A,$A$4,Database!$B:$B,$B9) -> 0 | I9: =SUMIFS(Database!$I:$I,Database!$A:$A,$A$4,Database!$B:$B,$B9) -> 0 | J9: =SUMIFS(Database!$J:$J,Database!$A:$A,$A$4,Database!$B:$B,$B9) -> 0 | K9: =SUMIFS(Database!$K:$K,Database!$A:$A,$A$4,Database!$B:$B,$B9) -> 0 | L9: =SUMIFS(Database!$L:$L,Database!$A:$A,$A$4,Database!$B:$B,$B9) -> 0 | M9: =SUMIFS(Database!$M:$M,Database!$A:$A,$A$4,Database!$B:$B,$B9) -> 15541.9 | N9: =SUMIFS(Database!$N:$N,Database!$A:$A,$A$4,Database!$B:$B,$B9) -> 10000 | O9: =SUMIFS(Database!$O:$O,Database!$A:$A,$A$4,Database!$B:$B,$B9) -> 30000 | P9: =SUMIFS(Database!$P:$P,Database!$A:$A,$A9,Database!$B:$B,$B9) -> 40000 | Z9: 2027
A10: =$A$4 -> 2026 | B10: Mar | C10: =SUMIFS(Database!$C:$C,Database!$A:$A,$A$4,Database!$B:$B,$B10) -> 10000 | D10: =SUMIFS(Database!$D:$D,Database!$A:$A,$A$4,Database!$B:$B,$B10) -> 8535.4 | E10: =SUMIFS(Database!$E:$E,Database!$A:$A,$A$4,Database!$B:$B,$B10) -> 36098.48 | F10: =SUMIFS(Database!$F:$F,Database!$A:$A,$A$4,Database!$B:$B,$B10) -> 960 | G10: =SUMIFS(Database!$G:$G,Database!$A:$A,$A$4,Database!$B:$B,$B10) -> -1081 | H10: =SUMIFS(Database!$H:$H,Database!$A:$A,$A$4,Database!$B:$B,$B10) -> 0 | I10: =SUMIFS(Database!$I:$I,Database!$A:$A,$A$4,Database!$B:$B,$B10) -> 7996.63 | J10: =SUMIFS(Database!$J:$J,Database!$A:$A,$A$4,Database!$B:$B,$B10) -> 0 | K10: =SUMIFS(Database!$K:$K,Database!$A:$A,$A$4,Database!$B:$B,$B10) -> 0 | L10: =SUMIFS(Database!$L:$L,Database!$A:$A,$A$4,Database!$B:$B,$B10) -> 0 | M10: =SUMIFS(Database!$M:$M,Database!$A:$A,$A$4,Database!$B:$B,$B10) -> 62509.51 | N10: =SUMIFS(Database!$N:$N,Database!$A:$A,$A$4,Database!$B:$B,$B10) -> 10000 | O10: =SUMIFS(Database!$O:$O,Database!$A:$A,$A$4,Database!$B:$B,$B10) -> 40000 | P10: =SUMIFS(Database!$P:$P,Database!$A:$A,$A10,Database!$B:$B,$B10) -> 50000 | Z10: 2028
A11: =$A$4 -> 2026 | B11: Apr | C11: =SUMIFS(Database!$C:$C,Database!$A:$A,$A$4,Database!$B:$B,$B11) -> 16000 | D11: =SUMIFS(Database!$D:$D,Database!$A:$A,$A$4,Database!$B:$B,$B11) -> 765 | E11: =SUMIFS(Database!$E:$E,Database!$A:$A,$A$4,Database!$B:$B,$B11) -> 28353.87 | F11: =SUMIFS(Database!$F:$F,Database!$A:$A,$A$4,Database!$B:$B,$B11) -> 1298 | G11: =SUMIFS(Database!$G:$G,Database!$A:$A,$A$4,Database!$B:$B,$B11) -> 5466 | H11: =SUMIFS(Database!$H:$H,Database!$A:$A,$A$4,Database!$B:$B,$B11) -> 18271 | I11: =SUMIFS(Database!$I:$I,Database!$A:$A,$A$4,Database!$B:$B,$B11) -> 809.25 | J11: =SUMIFS(Database!$J:$J,Database!$A:$A,$A$4,Database!$B:$B,$B11) -> 170 | K11: =SUMIFS(Database!$K:$K,Database!$A:$A,$A$4,Database!$B:$B,$B11) -> 0 | L11: =SUMIFS(Database!$L:$L,Database!$A:$A,$A$4,Database!$B:$B,$B11) -> 0 | M11: =SUMIFS(Database!$M:$M,Database!$A:$A,$A$4,Database!$B:$B,$B11) -> 71133.12 | N11: =SUMIFS(Database!$N:$N,Database!$A:$A,$A$4,Database!$B:$B,$B11) -> 15000 | O11: =SUMIFS(Database!$O:$O,Database!$A:$A,$A$4,Database!$B:$B,$B11) -> 3000 | P11: =SUMIFS(Database!$P:$P,Database!$A:$A,$A11,Database!$B:$B,$B11) -> 18000 | Z11: 2029
A12: =$A$4 -> 2026 | B12: May | C12: =SUMIFS(Database!$C:$C,Database!$A:$A,$A$4,Database!$B:$B,$B12) -> 16000 | D12: =SUMIFS(Database!$D:$D,Database!$A:$A,$A$4,Database!$B:$B,$B12) -> 419.1 | E12: =SUMIFS(Database!$E:$E,Database!$A:$A,$A$4,Database!$B:$B,$B12) -> 19759.59 | F12: =SUMIFS(Database!$F:$F,Database!$A:$A,$A$4,Database!$B:$B,$B12) -> 1255 | G12: =SUMIFS(Database!$G:$G,Database!$A:$A,$A$4,Database!$B:$B,$B12) -> 5299 | H12: =SUMIFS(Database!$H:$H,Database!$A:$A,$A$4,Database!$B:$B,$B12) -> 0 | I12: =SUMIFS(Database!$I:$I,Database!$A:$A,$A$4,Database!$B:$B,$B12) -> 4879 | J12: =SUMIFS(Database!$J:$J,Database!$A:$A,$A$4,Database!$B:$B,$B12) -> 1125 | K12: =SUMIFS(Database!$K:$K,Database!$A:$A,$A$4,Database!$B:$B,$B12) -> 3947 | L12: =SUMIFS(Database!$L:$L,Database!$A:$A,$A$4,Database!$B:$B,$B12) -> 0 | M12: =SUMIFS(Database!$M:$M,Database!$A:$A,$A$4,Database!$B:$B,$B12) -> 52683.69 | N12: =SUMIFS(Database!$N:$N,Database!$A:$A,$A$4,Database!$B:$B,$B12) -> 15000 | O12: =SUMIFS(Database!$O:$O,Database!$A:$A,$A$4,Database!$B:$B,$B12) -> 37000 | P12: =SUMIFS(Database!$P:$P,Database!$A:$A,$A12,Database!$B:$B,$B12) -> 52000 | Z12: 2030
A13: =$A$4 -> 2026 | B13: Jun | C13: =SUMIFS(Database!$C:$C,Database!$A:$A,$A$4,Database!$B:$B,$B13) -> 16000 | D13: =SUMIFS(Database!$D:$D,Database!$A:$A,$A$4,Database!$B:$B,$B13) -> 173 | E13: =SUMIFS(Database!$E:$E,Database!$A:$A,$A$4,Database!$B:$B,$B13) -> -3200.2 | F13: =SUMIFS(Database!$F:$F,Database!$A:$A,$A$4,Database!$B:$B,$B13) -> 175 | G13: =SUMIFS(Database!$G:$G,Database!$A:$A,$A$4,Database!$B:$B,$B13) -> 0 | H13: =SUMIFS(Database!$H:$H,Database!$A:$A,$A$4,Database!$B:$B,$B13) -> 0 | I13: =SUMIFS(Database!$I:$I,Database!$A:$A,$A$4,Database!$B:$B,$B13) -> 687.36 | J13: =SUMIFS(Database!$J:$J,Database!$A:$A,$A$4,Database!$B:$B,$B13) -> 1022.82 | K13: =SUMIFS(Database!$K:$K,Database!$A:$A,$A$4,Database!$B:$B,$B13) -> 0 | L13: =SUMIFS(Database!$L:$L,Database!$A:$A,$A$4,Database!$B:$B,$B13) -> 0 | M13: =SUMIFS(Database!$M:$M,Database!$A:$A,$A$4,Database!$B:$B,$B13) -> 14857.98 | N13: =SUMIFS(Database!$N:$N,Database!$A:$A,$A$4,Database!$B:$B,$B13) -> 0 | O13: =SUMIFS(Database!$O:$O,Database!$A:$A,$A$4,Database!$B:$B,$B13) -> 0 | P13: =SUMIFS(Database!$P:$P,Database!$A:$A,$A13,Database!$B:$B,$B13) -> 0
A14: =$A$4 -> 2026 | B14: Jul | C14: =SUMIFS(Database!$C:$C,Database!$A:$A,$A$4,Database!$B:$B,$B14) -> 0 | D14: =SUMIFS(Database!$D:$D,Database!$A:$A,$A$4,Database!$B:$B,$B14) -> 0 | E14: =SUMIFS(Database!$E:$E,Database!$A:$A,$A$4,Database!$B:$B,$B14) -> 0 | F14: =SUMIFS(Database!$F:$F,Database!$A:$A,$A$4,Database!$B:$B,$B14) -> 0 | G14: =SUMIFS(Database!$G:$G,Database!$A:$A,$A$4,Database!$B:$B,$B14) -> 0 | H14: =SUMIFS(Database!$H:$H,Database!$A:$A,$A$4,Database!$B:$B,$B14) -> 0 | I14: =SUMIFS(Database!$I:$I,Database!$A:$A,$A$4,Database!$B:$B,$B14) -> 0 | J14: =SUMIFS(Database!$J:$J,Database!$A:$A,$A$4,Database!$B:$B,$B14) -> 0 | K14: =SUMIFS(Database!$K:$K,Database!$A:$A,$A$4,Database!$B:$B,$B14) -> 0 | L14: =SUMIFS(Database!$L:$L,Database!$A:$A,$A$4,Database!$B:$B,$B14) -> 0 | M14: =SUMIFS(Database!$M:$M,Database!$A:$A,$A$4,Database!$B:$B,$B14) -> 0 | N14: =SUMIFS(Database!$N:$N,Database!$A:$A,$A$4,Database!$B:$B,$B14) -> 0 | O14: =SUMIFS(Database!$O:$O,Database!$A:$A,$A$4,Database!$B:$B,$B14) -> 0 | P14: 0
A15: =$A$4 -> 2026 | B15: Aug | C15: =SUMIFS(Database!$C:$C,Database!$A:$A,$A$4,Database!$B:$B,$B15) -> 0 | D15: =SUMIFS(Database!$D:$D,Database!$A:$A,$A$4,Database!$B:$B,$B15) -> 0 | E15: =SUMIFS(Database!$E:$E,Database!$A:$A,$A$4,Database!$B:$B,$B15) -> 0 | F15: =SUMIFS(Database!$F:$F,Database!$A:$A,$A$4,Database!$B:$B,$B15) -> 0 | G15: =SUMIFS(Database!$G:$G,Database!$A:$A,$A$4,Database!$B:$B,$B15) -> 0 | H15: =SUMIFS(Database!$H:$H,Database!$A:$A,$A$4,Database!$B:$B,$B15) -> 0 | I15: =SUMIFS(Database!$I:$I,Database!$A:$A,$A$4,Database!$B:$B,$B15) -> 0 | J15: =SUMIFS(Database!$J:$J,Database!$A:$A,$A$4,Database!$B:$B,$B15) -> 0 | K15: =SUMIFS(Database!$K:$K,Database!$A:$A,$A$4,Database!$B:$B,$B15) -> 0 | L15: =SUMIFS(Database!$L:$L,Database!$A:$A,$A$4,Database!$B:$B,$B15) -> 0 | M15: =SUMIFS(Database!$M:$M,Database!$A:$A,$A$4,Database!$B:$B,$B15) -> 0 | N15: =SUMIFS(Database!$N:$N,Database!$A:$A,$A$4,Database!$B:$B,$B15) -> 0 | O15: =SUMIFS(Database!$O:$O,Database!$A:$A,$A$4,Database!$B:$B,$B15) -> 0 | P15: =SUMIFS(Database!$P:$P,Database!$A:$A,$A15,Database!$B:$B,$B15) -> 0
A16: =$A$4 -> 2026 | B16: Sep | C16: =SUMIFS(Database!$C:$C,Database!$A:$A,$A$4,Database!$B:$B,$B16) -> 0 | D16: =SUMIFS(Database!$D:$D,Database!$A:$A,$A$4,Database!$B:$B,$B16) -> 0 | E16: =SUMIFS(Database!$E:$E,Database!$A:$A,$A$4,Database!$B:$B,$B16) -> 0 | F16: =SUMIFS(Database!$F:$F,Database!$A:$A,$A$4,Database!$B:$B,$B16) -> 0 | G16: =SUMIFS(Database!$G:$G,Database!$A:$A,$A$4,Database!$B:$B,$B16) -> 0 | H16: =SUMIFS(Database!$H:$H,Database!$A:$A,$A$4,Database!$B:$B,$B16) -> 0 | I16: =SUMIFS(Database!$I:$I,Database!$A:$A,$A$4,Database!$B:$B,$B16) -> 0 | J16: =SUMIFS(Database!$J:$J,Database!$A:$A,$A$4,Database!$B:$B,$B16) -> 0 | K16: =SUMIFS(Database!$K:$K,Database!$A:$A,$A$4,Database!$B:$B,$B16) -> 0 | L16: =SUMIFS(Database!$L:$L,Database!$A:$A,$A$4,Database!$B:$B,$B16) -> 0 | M16: =SUMIFS(Database!$M:$M,Database!$A:$A,$A$4,Database!$B:$B,$B16) -> 0 | N16: =SUMIFS(Database!$N:$N,Database!$A:$A,$A$4,Database!$B:$B,$B16) -> 0 | O16: =SUMIFS(Database!$O:$O,Database!$A:$A,$A$4,Database!$B:$B,$B16) -> 0 | P16: =SUMIFS(Database!$P:$P,Database!$A:$A,$A16,Database!$B:$B,$B16) -> 0
A17: =$A$4 -> 2026 | B17: Oct | C17: =SUMIFS(Database!$C:$C,Database!$A:$A,$A$4,Database!$B:$B,$B17) -> 0 | D17: =SUMIFS(Database!$D:$D,Database!$A:$A,$A$4,Database!$B:$B,$B17) -> 0 | E17: =SUMIFS(Database!$E:$E,Database!$A:$A,$A$4,Database!$B:$B,$B17) -> 0 | F17: =SUMIFS(Database!$F:$F,Database!$A:$A,$A$4,Database!$B:$B,$B17) -> 0 | G17: =SUMIFS(Database!$G:$G,Database!$A:$A,$A$4,Database!$B:$B,$B17) -> 0 | H17: =SUMIFS(Database!$H:$H,Database!$A:$A,$A$4,Database!$B:$B,$B17) -> 0 | I17: =SUMIFS(Database!$I:$I,Database!$A:$A,$A$4,Database!$B:$B,$B17) -> 0 | J17: =SUMIFS(Database!$J:$J,Database!$A:$A,$A$4,Database!$B:$B,$B17) -> 0 | K17: =SUMIFS(Database!$K:$K,Database!$A:$A,$A$4,Database!$B:$B,$B17) -> 0 | L17: =SUMIFS(Database!$L:$L,Database!$A:$A,$A$4,Database!$B:$B,$B17) -> 0 | M17: =SUMIFS(Database!$M:$M,Database!$A:$A,$A$4,Database!$B:$B,$B17) -> 0 | N17: =SUMIFS(Database!$N:$N,Database!$A:$A,$A$4,Database!$B:$B,$B17) -> 0 | O17: =SUMIFS(Database!$O:$O,Database!$A:$A,$A$4,Database!$B:$B,$B17) -> 0 | P17: =SUMIFS(Database!$P:$P,Database!$A:$A,$A17,Database!$B:$B,$B17) -> 0
A18: =$A$4 -> 2026 | B18: Nov | C18: =SUMIFS(Database!$C:$C,Database!$A:$A,$A$4,Database!$B:$B,$B18) -> 0 | D18: =SUMIFS(Database!$D:$D,Database!$A:$A,$A$4,Database!$B:$B,$B18) -> 0 | E18: =SUMIFS(Database!$E:$E,Database!$A:$A,$A$4,Database!$B:$B,$B18) -> 0 | F18: =SUMIFS(Database!$F:$F,Database!$A:$A,$A$4,Database!$B:$B,$B18) -> 0 | G18: =SUMIFS(Database!$G:$G,Database!$A:$A,$A$4,Database!$B:$B,$B18) -> 0 | H18: =SUMIFS(Database!$H:$H,Database!$A:$A,$A$4,Database!$B:$B,$B18) -> 0 | I18: =SUMIFS(Database!$I:$I,Database!$A:$A,$A$4,Database!$B:$B,$B18) -> 0 | J18: =SUMIFS(Database!$J:$J,Database!$A:$A,$A$4,Database!$B:$B,$B18) -> 0 | K18: =SUMIFS(Database!$K:$K,Database!$A:$A,$A$4,Database!$B:$B,$B18) -> 0 | L18: =SUMIFS(Database!$L:$L,Database!$A:$A,$A$4,Database!$B:$B,$B18) -> 0 | M18: =SUMIFS(Database!$M:$M,Database!$A:$A,$A$4,Database!$B:$B,$B18) -> 0 | N18: =SUMIFS(Database!$N:$N,Database!$A:$A,$A$4,Database!$B:$B,$B18) -> 0 | O18: =SUMIFS(Database!$O:$O,Database!$A:$A,$A$4,Database!$B:$B,$B18) -> 0 | P18: =SUMIFS(Database!$P:$P,Database!$A:$A,$A18,Database!$B:$B,$B18) -> 0
A19: =$A$4 -> 2026 | B19: Dec | C19: =SUMIFS(Database!$C:$C,Database!$A:$A,$A$4,Database!$B:$B,$B19) -> 0 | D19: =SUMIFS(Database!$D:$D,Database!$A:$A,$A$4,Database!$B:$B,$B19) -> 0 | E19: =SUMIFS(Database!$E:$E,Database!$A:$A,$A$4,Database!$B:$B,$B19) -> 0 | F19: =SUMIFS(Database!$F:$F,Database!$A:$A,$A$4,Database!$B:$B,$B19) -> 0 | G19: =SUMIFS(Database!$G:$G,Database!$A:$A,$A$4,Database!$B:$B,$B19) -> 0 | H19: =SUMIFS(Database!$H:$H,Database!$A:$A,$A$4,Database!$B:$B,$B19) -> 0 | I19: =SUMIFS(Database!$I:$I,Database!$A:$A,$A$4,Database!$B:$B,$B19) -> 0 | J19: =SUMIFS(Database!$J:$J,Database!$A:$A,$A$4,Database!$B:$B,$B19) -> 0 | K19: =SUMIFS(Database!$K:$K,Database!$A:$A,$A$4,Database!$B:$B,$B19) -> 0 | L19: =SUMIFS(Database!$L:$L,Database!$A:$A,$A$4,Database!$B:$B,$B19) -> 0 | M19: =SUMIFS(Database!$M:$M,Database!$A:$A,$A$4,Database!$B:$B,$B19) -> 0 | N19: =SUMIFS(Database!$N:$N,Database!$A:$A,$A$4,Database!$B:$B,$B19) -> 0 | O19: =SUMIFS(Database!$O:$O,Database!$A:$A,$A$4,Database!$B:$B,$B19) -> 0 | P19: =SUMIFS(Database!$P:$P,Database!$A:$A,$A19,Database!$B:$B,$B19) -> 0
C20: =SUM(C8:C19) -> 58000 | D20: =SUM(D8:D19) -> 10141 | E20: =SUM(E8:E19) -> 113119.6 | F20: =SUM(F8:F19) -> 3688 | G20: =SUM(G8:G19) -> 9922 | H20: =SUM(H8:H19) -> 18271 | I20: =SUM(I8:I19) -> 14859.79 | J20: =SUM(J8:J19) -> 2317.82 | ... P20: =SUM(P8:P19) -> 270000
A21: ⚠️Make entry in database and not dashboard

Sheet Database bkp
A1: Expense Database
C3: EXPENSES | N3: SAVINGS
A4: Year | B4: Month | C4: Home Rent | D4: Transport | E4: Shopping | F4: Office | G4: Bills | H4: Insurance | I4: Medical | J4: Fitness | K4: Travel | L4: Misc | M4: Total Spent | N4: Investments | O4: Personal | P4: Total Savings
A5: 2022 | B5: Jan
A6: 2022 | B6: Feb
A7: 2022 | B7: Mar | C7: 0 | D7: 800 | E7: 995 | F7: 0 | G7: 0 | H7: 0 | I7: 0 | J7: 0 | K7: 0 | L7: 0 | M7: 1795 | N7: 0 | O7: -1860.92 | P7: -1860.92
A8: 2022 | B8: Apr | C8: 0 | D8: 550 | E8: 16617 | F8: 0 | G8: 0 | H8: 0 | I8: 0 | J8: 0 | K8: 0 | L8: 0 | M8: 17167 | N8: 0 | O8: 0 | P8: 0
A9: 2022 | B9: May | C9: 0 | D9: 200 | E9: 24458 | F9: 0 | G9: 0 | H9: 0 | I9: 0 | J9: 0 | K9: 0 | L9: 0 | M9: 24658 | N9: 0 | O9: 0 | P9: 0
A10: 2022 | B10: Jun | C10: 0 | D10: 850 | E10: 31360 | F10: 0 | G10: 0 | H10: 0 | I10: 0 | J10: 0 | K10: 0 | L10: 0 | M10: 32210 | N10: 0 | O10: 0 | P10: 0
A11: 2022 | B11: Jul | C11: 7900 | D11: 303 | E11: 25906 | F11: 0 | G11: 0 | H11: 0 | I11: 0 | J11: 0 | K11: 0 | L11: 0 | M11: 34109 | N11: 0 | O11: 0 | P11: 0
A12: 2022 | B12: Aug | C12: 8500 | D12: 346 | E12: 22384 | F12: 0 | G12: 0 | H12: 0 | I12: 0 | J12: 0 | K12: 0 | L12: 0 | M12: 31230 | N12: 0 | O12: 0 | P12: 0
A13: 2022 | B13: Sep | C13: 8500 | D13: 450 | E13: 27231 | F13: 0 | G13: 0 | H13: 0 | I13: 0 | J13: 0 | K13: 0 | L13: 0 | M13: 36181 | N13: 0 | O13: 0 | P13: 0
A14: 2022 | B14: Oct | C14: 8500 | D14: 330 | E14: 26925 | F14: 0 | G14: 0 | H14: 0 | I14: 0 | J14: 0 | K14: 0 | L14: 0 | M14: 35755 | N14: 0 | O14: 5000 | P14: 5000
A15: 2022 | B15: Nov | C15: 7500 | D15: 572 | E15: 28252 | F15: 0 | G15: 0 | H15: 0 | I15: 0 | J15: 0 | K15: 0 | L15: 0 | M15: 36324 | N15: 0 | O15: 21825.03 | P15: 21825.03
A16: 2022 | B16: Dec | C16: 9000 | D16: 397 | E16: 30907 | F16: 0 | G16: 0 | H16: 0 | I16: 0 | J16: 0 | K16: 0 | L16: 0 | M16: 40304 | N16: 0 | O16: 20000 | P16: 20000
A17: 2023 | B17: Jan | C17: 9000 | D17: 60 | E17: 5392.71 | F17: 0 | G17: 1351.64 | H17: 0 | I17: 169 | J17: 525 | K17: 0 | L17: 0 | M17: 16498.35 | N17: 0 | O17: 12017.7 | P17: 12017.7
A18: 2023 | B18: Feb | C18: 9000 | D18: 40 | E18: 8294.19 | F18: 0 | G18: 395 | H18: 0 | I18: 33 | J18: 500 | K18: 0 | L18: 0 | M18: 18262.19 | N18: 0 | O18: 30000 | P18: 30000
... A40: 2024 | B40: Dec | C40: 3600 | D40: 3607.33 | E40: 46755.55 | F40: 0 | G40: 0 | H40: 3202 | I40: 35 | J40: 0 | K40: 0 | L40: 105 | M40: 57304.88 | N40: 0 | O40: 0 | P40: 0
A41: 2025 | B41: Jan | C41: 0 | D41: 7926 | E41: 29524.29 | F41: 0 | G41: -600 | H41: 0 | I41: 0 | J41: 0 | K41: 0 | L41: 0 | M41: =SUM(C41:L41) -> 36850.29 | N41: 25000 | O41: 41200 | P41: 66200
A42: 2025 | B42: Feb | C42: 16000 | D42: 722 | E42: 6648.12 | F42: 2042 | G42: 1919 | H42: 1601 | I42: 0 | J42: 0 | K42: 0 | L42: 0 | M42: =SUM(C42:L42) -> 28932.12 | N42: 0 | O42: 33000 | P42: 33000
A43: 2025 | B43: Mar | C43: 16000 | D43: 295 | E43: 17268.71 | F43: 885 | G43: 119 | H43: 1601 | I43: 0 | J43: 0 | K43: 0 | L43: 0 | M43: =SUM(C43:L43) -> 36168.71 | N43: 0 | O43: 27600 | P43: 27600
A44: 2025 | B44: Apr | C44: 16000 | D44: 444 | E44: 6311.21 | F44: 1615 | G44: 119 | H44: 2450 | I44: 6880 | J44: 0 | K44: 0 | L44: 0 | M44: =SUM(C44:L44) -> 33819.21 | N44: 0 | O44: -4000 | P44: -4000
A45: 2025 | B45: May | C45: 16000 | D45: 2354 | E45: 13717.59 | F45: 1375 | G45: 1919 | H45: 30603 | I45: 206329 | J45: 0 | K45: 0 | L45: 0 | M45: =SUM(C45:L45) -> 272297.59 | N45: 0 | O45: -130000 | P45: -130000
A46: 2025 | B46: Jun | C46: 16000 | D46: 1614.9 | E46: 3885 | F46: 470 | G46: 119 | H46: 0 | I46: 19010 | J46: 0 | K46: 0 | L46: 0 | M46: =SUM(C46:L46) -> 41098.9 | N46: 0 | O46: 35000 | P46: 35000
A47: 2025 | B47: Jul | C47: 16000 | D47: 843 | E47: 13325.66 | F47: 1858 | G47: 119 | H47: 0 | I47: 1212 | J47: 0 | K47: 0 | L47: 0 | M47: =SUM(C47:L47) -> 33357.66 | N47: 0 | O47: 60000 | P47: 60000
A48: 2025 | B48: Aug | C48: 16000 | D48: 1220 | E48: 9174.12 | F48: 1555 | G48: 1919 | H48: 0 | I48: 2701 | J48: 0 | K48: 0 | L48: 0 | M48: =SUM(C48:L48) -> 32569.12 | N48: 10000 | O48: 47000 | P48: 57000
A49: 2025 | B49: Sep | C49: 16000 | D49: 500 | E49: 113388.8 | F49: 1485 | G49: 119 | H49: 0 | I49: 0 | J49: 0 | K49: 0 | L49: 0 | M49: =SUM(C49:L49) -> 131492.8 | N49: 0 | O49: -2000 | P49: -2000
A50: 2025 | B50: Oct | C50: 16000 | D50: 5929 | E50: 34971.71 | F50: 759 | G50: 119 | H50: 0 | I50: 6016.7 | J50: 0 | K50: 4187.8 | L50: 0 | M50: =SUM(C50:L50) -> 67983.21 | N50: 10000 | O50: -40000 | P50: -30000
A51: 2025 | B51: Nov | C51: 16000 | D51: 580 | E51: 45886.49 | F51: 1580 | G51: 1919 | H51: 0 | I51: 7121 | J51: 0 | K51: 0 | L51: 0 | M51: =SUM(C51:L51) -> 73086.49 | N51: 10000 | O51: -13000 | P51: -3000
A52: 2025 | B52: Dec | C52: 11000 | D52: 409 | E52: 29879.13 | F52: 978.86 | G52: 119 | H52: 0 | I52: 0 | J52: 0 | K52: 11665 | L52: 0 | M52: =SUM(C52:L52) -> 54050.99 | N52: 20000 | O52: 0 | P52: 20000
... A58: 2026 | B58: Jun | C58: 16000 | D58: 173 | E58: -3200.2 | F58: 175 | G58: 0 | H58: 0 | I58: 687.36 | J58: 1022.82 | K58: 0 | L58: 0 | M58: =SUM(C58:L58) -> 14857.98 | N58: 0 | O58: 0 | P58: 0
A59: 2026 | B59: Jul
A60: 2026 | B60: Aug
A61: 2026 | B61: Sep
A62: 2026 | B62: Oct
A63: 2026 | B63: Nov
A64: 2026 | B64: Dec
A65: 2027 | B65: Jan
A66: 2027 | B66: Feb
A67: 2027 | B67: Mar
...

Sheet Database
A1: Expense Database
C3: EXPENSES | N3: SAVINGS
A4: Year | B4: Month | C4: Home Rent | D4: Transport | E4: Shopping | F4: Office | G4: Bills | H4: Insurance | I4: Medical | J4: Fitness | K4: Travel | L4: Misc | M4: Total Spent | N4: Investments | O4: Personal | P4: Total Savings
A5: 2022 | B5: Jan
A6: 2022 | B6: Feb
A7: 2022 | B7: Mar | C7: 0 | D7: 800 | E7: 995 | F7: 0 | G7: 0 | H7: 0 | I7: 0 | J7: 0 | K7: 0 | L7: 0 | M7: 1795 | N7: 0 | O7: -1860.92 | P7: -1860.92
A8: 2022 | B8: Apr | C8: 0 | D8: 550 | E8: 16617 | F8: 0 | G8: 0 | H8: 0 | I8: 0 | J8: 0 | K8: 0 | L8: 0 | M8: 17167 | N8: 0 | O8: 0 | P8: 0
A9: 2022 | B9: May | C9: 0 | D9: 200 | E9: 24458 | F9: 0 | G9: 0 | H9: 0 | I9: 0 | J9: 0 | K9: 0 | L9: 0 | M9: 24658 | N9: 0 | O9: 0 | P9: 0
A10: 2022 | B10: Jun | C10: 0 | D10: 850 | E10: 31360 | F10: 0 | G10: 0 | H10: 0 | I10: 0 | J10: 0 | K10: 0 | L10: 0 | M10: 32210 | N10: 0 | O10: 0 | P10: 0
A11: 2022 | B11: Jul | C11: 7900 | D11: 303 | E11: 25906 | F11: 0 | G11: 0 | H11: 0 | I11: 0 | J11: 0 | K11: 0 | L11: 0 | M11: 34109 | N11: 0 | O11: 0 | P11: 0
A12: 2022 | B12: Aug | C12: 8500 | D12: 346 | E12: 22384 | F12: 0 | G12: 0 | H12: 0 | I12: 0 | J12: 0 | K12: 0 | L12: 0 | M12: 31230 | N12: 0 | O12: 0 | P12: 0
A13: 2022 | B13: Sep | C13: 8500 | D13: 450 | E13: 27231 | F13: 0 | G13: 0 | H13: 0 | I13: 0 | J13: 0 | K13: 0 | L13: 0 | M13: 36181 | N13: 0 | O13: 0 | P13: 0
A14: 2022 | B14: Oct | C14: 8500 | D14: 330 | E14: 26925 | F14: 0 | G14: 0 | H14: 0 | I14: 0 | J14: 0 | K14: 0 | L14: 0 | M14: 35755 | N14: 0 | O14: 5000 | P14: 5000
A15: 2022 | B15: Nov | C15: 7500 | D15: 572 | E15: 28252 | F15: 0 | G15: 0 | H15: 0 | I15: 0 | J15: 0 | K15: 0 | L15: 0 | M15: 36324 | N15: 0 | O15: 21825.03 | P15: 21825.03
A16: 2022 | B16: Dec | C16: 9000 | D16: 397 | E16: 30907 | F16: 0 | G16: 0 | H16: 0 | I16: 0 | J16: 0 | K16: 0 | L16: 0 | M16: 40304 | N16: 0 | O16: 20000 | P16: 20000
A17: 2023 | B17: Jan | C17: 9000 | D17: 60 | E17: 5392.71 | F17: 0 | G17: 1351.64 | H17: 0 | I17: 169 | J17: 525 | K17: 0 | L17: 0 | M17: 16498.35 | N17: 0 | O17: 12017.7 | P17: 12017.7
A18: 2023 | B18: Feb | C18: 9000 | D18: 40 | E18: 8294.19 | F18: 0 | G18: 395 | H18: 0 | I18: 33 | J18: 500 | K18: 0 | L18: 0 | M18: 18262.19 | N18: 0 | O18: 30000 | P18: 30000
... A40: 2024 | B40: Dec | C40: 3600 | D40: 3607.33 | E40: 46755.55 | F40: 0 | G40: 0 | H40: 3202 | I40: 35 | J40: 0 | K40: 0 | L40: 105 | M40: 57304.88 | N40: 0 | O40: 0 | P40: 0
A41: 2025 | B41: Jan | C41: 0 | D41: 7926 | E41: 29524.29 | F41: 0 | G41: -600 | H41: 0 | I41: 0 | J41: 0 | K41: 0 | L41: 0 | M41: =SUM(C41:L41) -> 36850.29 | N41: 25000 | O41: 41200 | P41: 66200
A42: 2025 | B42: Feb | C42: 16000 | D42: 722 | E42: 6648.12 | F42: 2042 | G42: 1919 | H42: 1601 | I42: 0 | J42: 0 | K42: 0 | L42: 0 | M42: =SUM(C42:L42) -> 28932.12 | N42: 0 | O42: 33000 | P42: 33000
A43: 2025 | B43: Mar | C43: 16000 | D43: 295 | E43: 17268.71 | F43: 885 | G43: 119 | H43: 1601 | I43: 0 | J43: 0 | K43: 0 | L43: 0 | M43: =SUM(C43:L43) -> 36168.71 | N43: 0 | O43: 27600 | P43: 27600
A44: 2025 | B44: Apr | C44: 16000 | D44: 444 | E44: 6311.21 | F44: 1615 | G44: 119 | H44: 2450 | I44: 6880 | J44: 0 | K44: 0 | L44: 0 | M44: =SUM(C44:L44) -> 33819.21 | N44: 0 | O44: -4000 | P44: -4000
A45: 2025 | B45: May | C45: 16000 | D45: 2354 | E45: 13717.59 | F45: 1375 | G45: 1919 | H45: 30603 | I45: 206329 | J45: 0 | K45: 0 | L45: 0 | M45: =SUM(C45:L45) -> 272297.59 | N45: 0 | O45: -130000 | P45: -130000
A46: 2025 | B46: Jun | C46: 16000 | D46: 1614.9 | E46: 3885 | F46: 470 | G46: 119 | H46: 0 | I46: 19010 | J46: 0 | K46: 0 | L46: 0 | M46: =SUM(C46:L46) -> 41098.9 | N46: 0 | O46: 35000 | P46: 35000
A47: 2025 | B47: Jul | C47: 16000 | D47: 843 | E47: 13325.66 | F47: 1858 | G47: 119 | H47: 0 | I47: 1212 | J47: 0 | K47: 0 | L47: 0 | M47: =SUM(C47:L47) -> 33357.66 | N47: 0 | O47: 60000 | P47: 60000
A48: 2025 | B48: Aug | C48: 16000 | D48: 1220 | E48: 9174.12 | F48: 1555 | G48: 1919 | H48: 0 | I48: 2701 | J48: 0 | K48: 0 | L48: 0 | M48: =SUM(C48:L48) -> 32569.12 | N48: 10000 | O48: 47000 | P48: 57000
A49: 2025 | B49: Sep | C49: 16000 | D49: 500 | E49: 113388.8 | F49: 1485 | G49: 119 | H49: 0 | I49: 0 | J49: 0 | K49: 0 | L49: 0 | M49: =SUM(C49:L49) -> 131492.8 | N49: 0 | O49: -2000 | P49: -2000
A50: 2025 | B50: Oct | C50: 16000 | D50: 5929 | E50: 34971.71 | F50: 759 | G50: 119 | H50: 0 | I50: 6016.7 | J50: 0 | K50: 4187.8 | L50: 0 | M50: =SUM(C50:L50) -> 67983.21 | N50: 10000 | O50: -40000 | P50: -30000
A51: 2025 | B51: Nov | C51: 16000 | D51: 580 | E51: 45886.49 | F51: 1580 | G51: 1919 | H51: 0 | I51: 7121 | J51: 0 | K51: 0 | L51: 0 | M51: =SUM(C51:L51) -> 73086.49 | N51: 10000 | O51: -13000 | P51: -3000
A52: 2025 | B52: Dec | C52: 11000 | D52: 409 | E52: 29879.13 | F52: 978.86 | G52: 119 | H52: 0 | I52: 0 | J52: 0 | K52: 11665 | L52: 0 | M52: =SUM(C52:L52) -> 54050.99 | N52: 20000 | O52: 0 | P52: 20000
... A58: 2026 | B58: Jun | C58: 16000 | D58: 173 | E58: -3200.2 | F58: 175 | G58: 0 | H58: 0 | I58: 687.36 | J58: 1022.82 | K58: 0 | L58: 0 | M58: =SUM(C58:L58) -> 14857.98 | N58: 0 | O58: 0 | P58: 0
A59: 2026 | B59: Jul
A60: 2026 | B60: Aug
A61: 2026 | B61: Sep
A62: 2026 | B62: Oct
A63: 2026 | B63: Nov
A64: 2026 | B64: Dec
A65: 2027 | B65: Jan
A66: 2027 | B66: Feb
A67: 2027 | B67: Mar
...
